Workbook
Name result: Pivvot_2!$Z$23
Name Slicer_downtime_category: #N/A
Name Slicer_machine_id: #N/A
Name Slicer_shift1: #N/A

Sheet production_output
A1: output_id | B1: date | C1: machine_id | D1: shift | E1: product_code | F1: units_planned | G1: units_produced | H1: units_rejected | I1: scrap_rate_pct | J1: operator_id
A2: 1 | B2: 45292 | C2: MCH-001 | D2: Morning | E2: PROD-A02 | F2: 422 | G2: 352 | H2: 16 | I2: 4.55 | J2: OP-006
A3: 2 | B3: 45292 | C3: MCH-001 | D3: Afternoon | E3: PROD-A02 | F3: 367 | G3: 315 | H3: 14 | I3: 4.44 | J3: OP-010
A4: 3 | B4: 45292 | C4: MCH-001 | D4: Night | E4: PROD-B02 | F4: 536 | G4: 478 | H4: 16 | I4: 3.35 | J4: OP-004
A5: 4 | B5: 45292 | C5: MCH-002 | D5: Morning | E5: PROD-A01 | F5: 390 | G5: 387 | H5: 9 | I5: 2.33 | J5: OP-013
A6: 5 | B6: 45292 | C6: MCH-002 | D6: Afternoon | E6: PROD-A02 | F6: 469 | G6: 457 | H6: 20 | I6: 4.38 | J6: OP-008
A7: 6 | B7: 45292 | C7: MCH-002 | D7: Night | E7: PROD-B02 | F7: 335 | G7: 268 | H7: 0 | I7: 0 | J7: OP-014
A8: 7 | B8: 45292 | C8: MCH-003 | D8: Morning | E8: PROD-A01 | F8: 566 | G8: 565 | H8: 24 | I8: 4.25 | J8: OP-013
A9: 8 | B9: 45292 | C9: MCH-003 | D9: Afternoon | E9: PROD-C01 | F9: 513 | G9: 508 | H9: 22 | I9: 4.33 | J9: OP-002
A10: 9 | B10: 45292 | C10: MCH-003 | D10: Night | E10: PROD-A01 | F10: 573 | G10: 540 | H10: 11 | I10: 2.04 | J10: OP-005
A11: 10 | B11: 45292 | C11: MCH-004 | D11: Morning | E11: PROD-A01 | F11: 503 | G11: 485 | H11: 17 | I11: 3.51 | J11: OP-006
A12: 11 | B12: 45292 | C12: MCH-004 | D12: Afternoon | E12: PROD-B02 | F12: 504 | G12: 475 | H12: 12 | I12: 2.53 | J12: OP-007
A13: 12 | B13: 45292 | C13: MCH-004 | D13: Night | E13: PROD-C01 | F13: 363 | G13: 297 | H13: 12 | I13: 4.04 | J13: OP-013
... A1351: 1350 | B1351: 45381 | C1351: MCH-005 | D1351: Night | E1351: PROD-A02 | F1351: 431 | G1351: 389 | H1351: 17 | I1351: 4.37 | J1351: OP-006

Sheet oee_daily
A1: record_id | B1: date | C1: machine_id | D1: shift | E1: planned_production_time_min | F1: actual_run_time_min | G1: downtime_min | H1: total_units_produced | I1: good_units | J1: rejected_units | K1: ideal_cycle_time_sec | L1: availability | M1: performance | N1: quality | O1: oee
A2: 1 | B2: 45292 | C2: MCH-001 | D2: Morning | E2: 480 | F2: 453 | G2: 27 | H2: 979 | I2: 952 | J2: 27 | K2: 24.65 | L2: 0.9437 | M2: 0.8884 | N2: 0.9724 | O2: 0.8152 | Q2: =952/979 -> 0.97242084
A3: 2 | B3: 45292 | C3: MCH-001 | D3: Afternoon | E3: 480 | F3: 389 | G3: 91 | H3: 618 | I3: 612 | J3: 6 | K3: 33 | L3: 0.8104 | M3: 0.8741 | N3: 0.9903 | O3: 0.7015
A4: 3 | B4: 45292 | C4: MCH-001 | D4: Night | E4: 480 | F4: 405 | G4: 75 | H4: 902 | I4: 868 | J4: 34 | K4: 25.56 | L4: 0.8438 | M4: 0.9495 | N4: 0.9623 | O4: 0.771
A5: 4 | B5: 45292 | C5: MCH-002 | D5: Morning | E5: 480 | F5: 460 | G5: 20 | H5: 672 | I5: 667 | J5: 5 | K5: 33.96 | L5: 0.9583 | M5: 0.8276 | N5: 0.9926 | O5: 0.7872
A6: 5 | B6: 45292 | C6: MCH-002 | D6: Afternoon | E6: 480 | F6: 383 | G6: 97 | H6: 662 | I6: 659 | J6: 3 | K6: 26.73 | L6: 0.7979 | M6: 0.7707 | N6: 0.9955 | O6: 0.6122
A7: 6 | B7: 45292 | C7: MCH-002 | D7: Night | E7: 480 | F7: 372 | G7: 108 | H7: 672 | I7: 671 | J7: 1 | K7: 26.88 | L7: 0.775 | M7: 0.8096 | N7: 0.9985 | O7: 0.6265
A8: 7 | B8: 45292 | C8: MCH-003 | D8: Morning | E8: 480 | F8: 422 | G8: 58 | H8: 802 | I8: 787 | J8: 15 | K8: 30.72 | L8: 0.8792 | M8: 0.9733 | N8: 0.9813 | O8: 0.8397
A9: 8 | B9: 45292 | C9: MCH-003 | D9: Afternoon | E9: 480 | F9: 410 | G9: 70 | H9: 850 | I9: 813 | J9: 37 | K9: 25.86 | L9: 0.8542 | M9: 0.8938 | N9: 0.9565 | O9: 0.7303
A10: 9 | B10: 45292 | C10: MCH-003 | D10: Night | E10: 480 | F10: 434 | G10: 46 | H10: 752 | I10: 751 | J10: 1 | K10: 31.55 | L10: 0.9042 | M10: 0.9115 | N10: 0.9987 | O10: 0.8231
A11: 10 | B11: 45292 | C11: MCH-004 | D11: Morning | E11: 480 | F11: 451 | G11: 29 | H11: 745 | I11: 714 | J11: 31 | K11: 35.46 | L11: 0.9396 | M11: 0.9764 | N11: 0.9584 | O11: 0.8793
A12: 11 | B12: 45292 | C12: MCH-004 | D12: Afternoon | E12: 480 | F12: 370 | G12: 110 | H12: 820 | I12: 794 | J12: 26 | K12: 22.02 | L12: 0.7708 | M12: 0.8135 | N12: 0.9683 | O12: 0.6072
A13: 12 | B13: 45292 | C13: MCH-004 | D13: Night | E13: 480 | F13: 434 | G13: 46 | H13: 930 | I13: 899 | J13: 31 | K13: 23.25 | L13: 0.9042 | M13: 0.8311 | N13: 0.9667 | O13: 0.7265
A14: 13 | B14: 45292 | C14: MCH-005 | D14: Morning | E14: 480 | F14: 391 | G14: 89 | H14: 543 | I14: 527 | J14: 16 | K14: 38.73 | L14: 0.8146 | M14: 0.8975 | N14: 0.9705 | O14: 0.7095
... A1351: 1350 | B1351: 45381 | C1351: MCH-005 | D1351: Night | E1351: 480 | F1351: 431 | G1351: 49 | H1351: 640 | I1351: 640 | J1351: 0 | K1351: 37.81 | L1351: 0.8979 | M1351: 0.937 | N1351: 1 | O1351: 0.8413

Sheet maintenance_logs
A1: log_id | B1: date | C1: machine_id | D1: maintenance_type | E1: technician_id | F1: duration_hr | G1: parts_replaced | H1: cost_usd | I1: result
A2: 1 | B2: 45292 | C2: MCH-005 | D2: Inspection | E2: TECH-04 | F2: 7 | G2: Bearing | H2: 1959.08 | I2: Partially Resolved | J2: =IFERROR(AVERAGEIFS(oee_daily!O:O, oee_daily!C:C, C2, oee_daily!B:B, "<"&B2, oee_daily!B:B, ">="&IFERROR(_xlfn.MAXIFS($B$1:B1, $C$1:C1, C2), 0)), 0) -> 0
A3: 2 | B3: 45292 | C3: MCH-001 | D3: Inspection | E3: TECH-03 | F3: 2 | G3: Coolant Filter | H3: 1118.51 | I3: Escalated
A4: 3 | B4: 45299 | C4: MCH-002 | D4: Predictive | E4: TECH-03 | F4: 6.5 | G4: Sensor | H4: 796.12 | I4: Resolved
A5: 4 | B5: 45299 | C5: MCH-003 | D5: Preventive | E5: TECH-04 | F5: 3 | G5: Coolant Filter | H5: 153.49 | I5: Resolved
A6: 5 | B6: 45299 | C6: MCH-001 | D6: Inspection | E6: TECH-03 | F6: 3.2 | G6: Bearing | H6: 1258.76 | I6: Resolved
A7: 6 | B7: 45306 | C7: MCH-002 | D7: Corrective | E7: TECH-01 | F7: 6 | G7: Motor Brush | H7: 68.98 | I7: Resolved
A8: 7 | B8: 45306 | C8: MCH-005 | D8: Predictive | E8: TECH-03 | F8: 1.3 | G8: None | H8: 1012.1 | I8: Resolved
A9: 8 | B9: 45313 | C9: MCH-005 | D9: Preventive | E9: TECH-04 | F9: 7.6 | G9: Motor Brush | H9: 1993.72 | I9: Partially Resolved
A10: 9 | B10: 45313 | C10: MCH-001 | D10: Preventive | E10: TECH-02 | F10: 5 | G10: Coolant Filter | H10: 1389.02 | I10: Resolved
A11: 10 | B11: 45313 | C11: MCH-004 | D11: Inspection | E11: TECH-02 | F11: 5.6 | G11: Belt | H11: 155.27 | I11: Resolved
A12: 11 | B12: 45320 | C12: MCH-005 | D12: Corrective | E12: TECH-03 | F12: 2.9 | G12: None | H12: 1843.84 | I12: Resolved
A13: 12 | B13: 45320 | C13: MCH-003 | D13: Corrective | E13: TECH-02 | F13: 8 | G13: Belt | H13: 1791.29 | I13: Partially Resolved
A14: 13 | B14: 45327 | C14: MCH-005 | D14: Preventive | E14: TECH-01 | F14: 0.6 | G14: Bearing | H14: 1726.87 | I14: Resolved
... A29: 28 | B29: 45376 | C29: MCH-004 | D29: Inspection | E29: TECH-02 | F29: 3.9 | G29: Coolant Filter | H29: 1529.59 | I29: Resolved

Sheet machines
A1: machine_id | B1: machine_name | C1: line | D1: machine_type | E1: installation_year | F1: rated_capacity_units_per_hr | G1: maintenance_interval_days
A2: MCH-001 | B2: Machine MCH-001 | C2: Line-A | D2: CNC Lathe | E2: 2016 | F2: 83 | G2: 90
A3: MCH-002 | B3: Machine MCH-002 | C3: Line-A | D3: Press | E3: 2019 | F3: 111 | G3: 30
A4: MCH-003 | B4: Machine MCH-003 | C4: Line-B | D4: Injection Molder | E4: 2017 | F4: 174 | G4: 30
A5: MCH-004 | B5: Machine MCH-004 | C5: Line-B | D5: Conveyor | E5: 2016 | F5: 155 | G5: 60
A6: MCH-005 | B6: Machine MCH-005 | C6: Line-C | D6: Welder | E6: 2015 | F6: 83 | G6: 30

Sheet downtime_events
A1: event_id | B1: date | C1: machine_id | D1: shift | E1: start_time | F1: end_time | G1: duration_min | H1: downtime_reason | I1: downtime_category | J1: reported_by | K1: notes
A2: 1 | B2: 45292 | C2: MCH-001 | D2: Morning | E2: 0.25 | F2: 0.26527778 | G2: 22 | H2: Scheduled Maintenance | I2: Planned | J2: OP-003
A3: 2 | B3: 45292 | C3: MCH-001 | D3: Morning | E3: 0.28680556 | F3: 0.29027778 | G3: 5 | H3: Material Shortage | I3: Unplanned | J3: OP-002
A4: 3 | B4: 45292 | C4: MCH-001 | D4: Afternoon | E4: 0.58333333 | F4: 0.60972222 | G4: 38 | H4: Line Changeover | I4: Planned | J4: OP-014
A5: 4 | B5: 45292 | C5: MCH-001 | D5: Afternoon | E5: 0.64444444 | F5: 0.63611111 | G5: 48 | H5: Scheduled Maintenance | I5: Planned | J5: OP-007
A6: 5 | B6: 45292 | C6: MCH-001 | D6: Night | E6: 0.91666667 | F6: 0.92638889 | G6: 14 | H6: Tooling Change | I6: Planned | J6: OP-005
A7: 6 | B7: 45292 | C7: MCH-001 | D7: Night | E7: 0.95972222 | F7: 0.97777778 | G7: 26 | H7: Overheating | I7: Unplanned | J7: OP-009
A8: 7 | B8: 45292 | C8: MCH-001 | D8: Night | E8: 0.99027778 | F8: 0.96111111 | G8: 18 | H8: Material Shortage | I8: Unplanned | J8: OP-010
A9: 8 | B9: 45292 | C9: MCH-002 | D9: Morning | E9: 0.25 | F9: 0.26388889 | G9: 20 | H9: Scheduled Maintenance | I9: Planned | J9: OP-014
A10: 9 | B10: 45292 | C10: MCH-002 | D10: Afternoon | E10: 0.58333333 | F10: 0.61736111 | G10: 49 | H10: Software Error | I10: Unplanned | J10: OP-015
A11: 10 | B11: 45292 | C11: MCH-002 | D11: Afternoon | E11: 0.62986111 | F11: 0.65208333 | G11: 32 | H11: Material Shortage | I11: Unplanned | J11: OP-011
A12: 11 | B12: 45292 | C12: MCH-002 | D12: Night | E12: 0.91666667 | F12: 0.93402778 | G12: 25 | H12: Electrical Fault | I12: Unplanned | J12: OP-009
A13: 12 | B13: 45292 | C13: MCH-003 | D13: Morning | E13: 0.25 | F13: 0.25833333 | G13: 12 | H13: Material Shortage | I13: Unplanned | J13: OP-006
... A2211: 2210 | B2211: 45381 | C2211: MCH-005 | D2211: Night | E2211: 0.91666667 | F2211: 0.95069444 | G2211: 49 | H2211: Material Shortage | I2211: Unplanned | J2211: OP-008

Sheet Sheet4
A1: shift
A2: Afternoon
A3: Morning
A4: Night

Sheet Pivot_1
A1: Row Labels | B1: Sum of units_produced | C1: =GETPIVOTDATA("[Measures].[Sum of units_produced]",$A$1)/1000 -> 548.641 | E1: Row Labels | F1: Average of availability | G1: Average of performance | H1: Average of quality
A2: MCH-001 | B2: 111939 | E2: Afternoon
A3: MCH-005 | B3: 110243 | E3: MCH-001 | F3: 0.8724837 | G3: 0.86886519 | H3: 0.97592741
A4: MCH-002 | B4: 109476 | E4: MCH-002 | F4: 0.86886556 | G4: 0.8580563 | H4: 0.97747519
A5: MCH-004 | B5: 109461 | E5: MCH-003 | F5: 0.87283074 | G5: 0.87057 | H5: 0.97465519
A6: MCH-003 | B6: 107522 | E6: MCH-004 | F6: 0.86478111 | G6: 0.87003296 | H6: 0.97687296
A7: Grand Total | B7: 548641 | E7: MCH-005 | F7: 0.87581185 | G7: 0.86493296 | H7: 0.97652296
E8: Grand Total | F8: 0.87095459 | G8: 0.86649148 | H8: 0.97629074
A9: Row Labels | B9: Average of oee | C9: =GETPIVOTDATA("[Measures].[Average of oee]",$A$9) -> 0.73672148
A10: MCH-001 | B10: 0.73962889
A11: MCH-002 | B11: 0.72895333 | J11: Row Labels | K11: Count of downtime_reason
A12: MCH-003 | B12: 0.74012667 | J12: Operator Break | K12: 83
A13: MCH-004 | B13: 0.7351763 | J13: Line Changeover | K13: 79
A14: MCH-005 | B14: 0.73972222 | J14: Tooling Change | K14: 78
A15: Grand Total | B15: 0.73672148 | J15: Scheduled Maintenance | K15: 77
J16: Material Shortage | K16: 76
A17: Row Labels | B17: Sum of cost_usd | C17: =GETPIVOTDATA("[Measures].[Sum of cost_usd]",$A$17)/1000 -> 32.79813 | J17: Software Error | K17: 72
A18: MCH-005 | B18: 11800.15 | J18: Electrical Fault | K18: 69
A19: MCH-003 | B19: 9183.27 | J19: Mechanical Failure | K19: 67
A20: MCH-001 | B20: 6310.14 | J20: Quality Check | K20: 65
A21: MCH-004 | B21: 4639.47 | J21: Overheating | K21: 58
A22: MCH-002 | B22: 865.1 | J22: Grand Total | K22: 724
A23: Grand Total | B23: 32798.13
A25: Row Labels | B25: Sum of duration_min | C25: =GETPIVOTDATA("[Measures].[Sum of duration_min]",$H$27)/60 -> 322.35
A26: MCH-001 | B26: 4140
A27: MCH-002 | B27: 3647 | H27: Row Labels | I27: Sum of duration_min | J27: =GETPIVOTDATA("[Measures].[Sum of duration_min]",$H$27) -> 19341
A28: MCH-003 | B28: 3974 | H28: MCH-001
A29: MCH-004 | B29: 3873 | H29: Afternoon | I29: 4140
A30: MCH-005 | B30: 3707 | H30: MCH-002
A31: Grand Total | B31: 19341 | E31: Row Labels | F31: Average of oee | H31: Afternoon | I31: 3647
E32: Afternoon | F32: 0.73698 | H32: MCH-003
E33: Morning | F33: 0.73608822 | H33: Afternoon | I33: 3974
E34: Night | F34: 0.73709622 | H34: MCH-004
E35: Grand Total | F35: 0.73672148 | H35: Afternoon | I35: 3873
H36: MCH-005
H37: Afternoon | I37: 3707
H38: Grand Total | I38: 19341
J48: =GETPIVOTDATA("[Measures].[Sum of duration_min]",$H$27)/60 -> 322.35
A49: Row Labels | B49: Sum of units_produced
A50: Jan | B50: 187613
...

Sheet Pivvot_2
A1: date | B1: machine_id | C1: Days since last service | D1: Row Labels | E1: Average of Days since last service | G1: date | H1: machine_id | I1: OEE Before | J1: OEE After: | K1: cost_usd | L1: OEE_improvement | M1: technician_id | N1: Spend_Efficiency | O1: Row Labels | P1: Average of OEE_improvement | W1: Row Labels | X1: Sum of duration_min | Y1: =GETPIVOTDATA("[Measures].[Sum of duration_min]",$W$1)/60 -> 322.35 | Z1: Row Labels | AA1: Count of parts_replaced | AB1: Average of cost_usd
A2: 45292 | B2: MCH-005 | C2: {=IFERROR(A2 - LOOKUP(2,1/($B$2:$B$100=B2)/($A$2:$A$100<A2),$A$2:$A$100),0)} -> 0 | D2: MCH-001 | E2: 11.666667 | G2: 45292 | H2: MCH-005 | I2: =IFERROR(AVERAGEIFS(oee_daily!O:O,oee_daily!C:C,H2,oee_daily!B:B,"<"&G2),0) -> 0 | J2: =IF(_xlfn.MINIFS($G$3:$G$1000, $H$3:$H$1000, H2, $G$3:$G$1000, ">"&G2)=0, 0, IFERROR(AVERAGEIFS(oee_daily!O:O, oee_daily!C:C, H2, oee_daily!B:B, ">"&G2, oee_daily!B:B, "<="&_xlfn.MINIFS($G$3:$G$1000, $H$3:$H$1000, H2, $G$3:$G$1000, ">"&G2)), 0)) -> 0.74589762 | K2: 1959.08 | L2: =IF(OR(I2=0, J2=0), 0, J2-I2) -> 0 | M2: TECH-04 | N2: =IFERROR(L2/K2,0) -> 0 | O2: MCH-001 | P2: 0.012950595 | W2: MCH-001 | Z2: Bearing | AA2: 9 | AB2: 1117.9656
A3: 45292 | B3: MCH-001 | C3: {=IFERROR(A3 - LOOKUP(2,1/($B$2:$B$100=B3)/($A$2:$A$100<A3),$A$2:$A$100),0)} -> 0 | D3: MCH-005 | E3: 11 | G3: 45292 | H3: MCH-001 | I3: =IFERROR(AVERAGEIFS(oee_daily!O:O,oee_daily!C:C,H3,oee_daily!B:B,"<"&G3),0) -> 0 | J3: =IF(_xlfn.MINIFS($G$3:$G$1000, $H$3:$H$1000, H3, $G$3:$G$1000, ">"&G3)=0, 0, IFERROR(AVERAGEIFS(oee_daily!O:O, oee_daily!C:C, H3, oee_daily!B:B, ">"&G3, oee_daily!B:B, "<="&_xlfn.MINIFS($G$3:$G$1000, $H$3:$H$1000, H3, $G$3:$G$1000, ">"&G3)), 0)) -> 0.7121619 | K3: 1118.51 | L3: =IF(OR(I3=0, J3=0), 0, J3-I3) -> 0 | M3: TECH-03 | N3: =IFERROR(L3/K3,0) -> 0 | O3: MCH-004 | P3: 0.0050544432 | W3: Planned | X3: 2037 | Z3: Belt | AA3: 3 | AB3: 1291.5867
A4: 45299 | B4: MCH-002 | C4: {=IFERROR(A4 - LOOKUP(2,1/($B$2:$B$100=B4)/($A$2:$A$100<A4),$A$2:$A$100),0)} -> 0 | D4: MCH-004 | E4: 10.5 | G4: 45299 | H4: MCH-002 | I4: =IFERROR(AVERAGEIFS(oee_daily!O:O,oee_daily!C:C,H4,oee_daily!B:B,"<"&G4),0) -> 0.74228571 | J4: =IF(_xlfn.MINIFS($G$3:$G$1000, $H$3:$H$1000, H4, $G$3:$G$1000, ">"&G4)=0, 0, IFERROR(AVERAGEIFS(oee_daily!O:O, oee_daily!C:C, H4, oee_daily!B:B, ">"&G4, oee_daily!B:B, "<="&_xlfn.MINIFS($G$3:$G$1000, $H$3:$H$1000, H4, $G$3:$G$1000, ">"&G4)), 0)) -> 0.73598571 | K4: 796.12 | L4: =IF(OR(I4=0, J4=0), 0, J4-I4) -> -0.0063 | M4: TECH-03 | N4: =IFERROR(L4/K4,0) -> -7.9133799e-06 | O4: MCH-003 | P4: 0.00096325451 | W4: Unplanned | X4: 2103 | Z4: Coolant Filter | AA4: 7 | AB4: 1210.4757
A5: 45299 | B5: MCH-003 | C5: {=IFERROR(A5 - LOOKUP(2,1/($B$2:$B$100=B5)/($A$2:$A$100<A5),$A$2:$A$100),0)} -> 0 | D5: MCH-003 | E5: 10 | G5: 45299 | H5: MCH-003 | I5: =IFERROR(AVERAGEIFS(oee_daily!O:O,oee_daily!C:C,H5,oee_daily!B:B,"<"&G5),0) -> 0.74432857 | J5: =IF(_xlfn.MINIFS($G$3:$G$1000, $H$3:$H$1000, H5, $G$3:$G$1000, ">"&G5)=0, 0, IFERROR(AVERAGEIFS(oee_daily!O:O, oee_daily!C:C, H5, oee_daily!B:B, ">"&G5, oee_daily!B:B, "<="&_xlfn.MINIFS($G$3:$G$1000, $H$3:$H$1000, H5, $G$3:$G$1000, ">"&G5)), 0)) -> 0.74100159 | K5: 153.49 | L5: =IF(OR(I5=0, J5=0), 0, J5-I5) -> -0.0033269841 | M5: TECH-04 | N5: =IFERROR(L5/K5,0) -> -2.1675576e-05 | O5: MCH-005 | P5: -0.00074095076 | W5: MCH-002 | Z5: Motor Brush | AA5: 4 | AB5: 1307.52
A6: 45299 | B6: MCH-001 | C6: {=IFERROR(A6 - LOOKUP(2,1/($B$2:$B$100=B6)/($A$2:$A$100<A6),$A$2:$A$100),0)} -> 7 | D6: MCH-002 | E6: 3.5 | G6: 45299 | H6: MCH-001 | I6: =IFERROR(AVERAGEIFS(oee_daily!O:O,oee_daily!C:C,H6,oee_daily!B:B,"<"&G6),0) -> 0.71003333 | J6: =IF(_xlfn.MINIFS($G$3:$G$1000, $H$3:$H$1000, H6, $G$3:$G$1000, ">"&G6)=0, 0, IFERROR(AVERAGEIFS(oee_daily!O:O, oee_daily!C:C, H6, oee_daily!B:B, ">"&G6, oee_daily!B:B, "<="&_xlfn.MINIFS($G$3:$G$1000, $H$3:$H$1000, H6, $G$3:$G$1000, ">"&G6)), 0)) -> 0.72215238 | K6: 1258.76 | L6: =IF(OR(I6=0, J6=0), 0, J6-I6) -> 0.012119048 | M6: TECH-03 | N6: =IFERROR(L6/K6,0) -> 9.6277667e-06 | O6: MCH-002 | P6: -0.00315 | W6: Planned | X6: 1862 | Z6: None | AA6: 4 | AB6: 1090.5375
A7: 45306 | B7: MCH-002 | C7: {=IFERROR(A7 - LOOKUP(2,1/($B$2:$B$100=B7)/($A$2:$A$100<A7),$A$2:$A$100),0)} -> 7 | D7: Grand Total | E7: 10.25 | G7: 45306 | H7: MCH-002 | I7: =IFERROR(AVERAGEIFS(oee_daily!O:O,oee_daily!C:C,H7,oee_daily!B:B,"<"&G7),0) -> 0.73510238 | J7: =IF(_xlfn.MINIFS($G$3:$G$1000, $H$3:$H$1000, H7, $G$3:$G$1000, ">"&G7)=0, 0, IFERROR(AVERAGEIFS(oee_daily!O:O, oee_daily!C:C, H7, oee_daily!B:B, ">"&G7, oee_daily!B:B, "<="&_xlfn.MINIFS($G$3:$G$1000, $H$3:$H$1000, H7, $G$3:$G$1000, ">"&G7)), 0)) -> 0 | K7: 68.98 | L7: =IF(OR(I7=0, J7=0), 0, J7-I7) -> 0 | M7: TECH-01 | N7: =IFERROR(L7/K7,0) -> 0 | O7: Grand Total | P7: 0.0036887985 | W7: Unplanned | X7: 1785 | Z7: Sensor | AA7: 1 | AB7: 796.12
A8: 45306 | B8: MCH-005 | C8: {=IFERROR(A8 - LOOKUP(2,1/($B$2:$B$100=B8)/($A$2:$A$100<A8),$A$2:$A$100),0)} -> 14 | G8: 45306 | H8: MCH-005 | I8: =IFERROR(AVERAGEIFS(oee_daily!O:O,oee_daily!C:C,H8,oee_daily!B:B,"<"&G8),0) -> 0.74334524 | J8: =IF(_xlfn.MINIFS($G$3:$G$1000, $H$3:$H$1000, H8, $G$3:$G$1000, ">"&G8)=0, 0, IFERROR(AVERAGEIFS(oee_daily!O:O, oee_daily!C:C, H8, oee_daily!B:B, ">"&G8, oee_daily!B:B, "<="&_xlfn.MINIFS($G$3:$G$1000, $H$3:$H$1000, H8, $G$3:$G$1000, ">"&G8)), 0)) -> 0.7670381 | K8: 1012.1 | L8: =IF(OR(I8=0, J8=0), 0, J8-I8) -> 0.023692857 | M8: TECH-03 | N8: =IFERROR(L8/K8,0) -> 2.3409601e-05 | W8: MCH-003 | Z8: Grand Total | AA8: 28 | AB8: 1171.3618
A9: 45313 | B9: MCH-005 | C9: {=IFERROR(A9 - LOOKUP(2,1/($B$2:$B$100=B9)/($A$2:$A$100<A9),$A$2:$A$100),0)} -> 7 | G9: 45313 | H9: MCH-005 | I9: =IFERROR(AVERAGEIFS(oee_daily!O:O,oee_daily!C:C,H9,oee_daily!B:B,"<"&G9),0) -> 0.75191587 | J9: =IF(_xlfn.MINIFS($G$3:$G$1000, $H$3:$H$1000, H9, $G$3:$G$1000, ">"&G9)=0, 0, IFERROR(AVERAGEIFS(oee_daily!O:O, oee_daily!C:C, H9, oee_daily!B:B, ">"&G9, oee_daily!B:B, "<="&_xlfn.MINIFS($G$3:$G$1000, $H$3:$H$1000, H9, $G$3:$G$1000, ">"&G9)), 0)) -> 0.75314762 | K9: 1993.72 | L9: =IF(OR(I9=0, J9=0), 0, J9-I9) -> 0.001231746 | M9: TECH-04 | N9: =IFERROR(L9/K9,0) -> 6.1781295e-07 | O9: Row Labels | P9: Average of OEE_improvement | W9: Planned | X9: 2074
A10: 45313 | B10: MCH-001 | C10: {=IFERROR(A10 - LOOKUP(2,1/($B$2:$B$100=B10)/($A$2:$A$100<A10),$A$2:$A$100),0)} -> 14 | G10: 45313 | H10: MCH-001 | I10: =IFERROR(AVERAGEIFS(oee_daily!O:O,oee_daily!C:C,H10,oee_daily!B:B,"<"&G10),0) -> 0.72045873 | J10: =IF(_xlfn.MINIFS($G$3:$G$1000, $H$3:$H$1000, H10, $G$3:$G$1000, ">"&G10)=0, 0, IFERROR(AVERAGEIFS(oee_daily!O:O, oee_daily!C:C, H10, oee_daily!B:B, ">"&G10, oee_daily!B:B, "<="&_xlfn.MINIFS($G$3:$G$1000, $H$3:$H$1000, H10, $G$3:$G$1000, ">"&G10)), 0)) -> 0.73648095 | K10: 1389.02 | L10: =IF(OR(I10=0, J10=0), 0, J10-I10) -> 0.016022222 | M10: TECH-02 | N10: =IFERROR(L10/K10,0) -> 1.1534911e-05 | O10: TECH-03 | P10: 0.0098757937 | W10: Unplanned | X10: 1900
A11: 45313 | B11: MCH-004 | C11: {=IFERROR(A11 - LOOKUP(2,1/($B$2:$B$100=B11)/($A$2:$A$100<A11),$A$2:$A$100),0)} -> 0 | G11: 45313 | H11: MCH-004 | I11: =IFERROR(AVERAGEIFS(oee_daily!O:O,oee_daily!C:C,H11,oee_daily!B:B,"<"&G11),0) -> 0.72956508 | J11: =IF(_xlfn.MINIFS($G$3:$G$1000, $H$3:$H$1000, H11, $G$3:$G$1000, ">"&G11)=0, 0, IFERROR(AVERAGEIFS(oee_daily!O:O, oee_daily!C:C, H11, oee_daily!B:B, ">"&G11, oee_daily!B:B, "<="&_xlfn.MINIFS($G$3:$G$1000, $H$3:$H$1000, H11, $G$3:$G$1000, ">"&G11)), 0)) -> 0.72656508 | K11: 155.27 | L11: =IF(OR(I11=0, J11=0), 0, J11-I11) -> -0.003 | M11: TECH-02 | N11: =IFERROR(L11/K11,0) -> -1.9321182e-05 | O11: TECH-04 | P11: 0.0065240079 | W11: MCH-004
A12: 45320 | B12: MCH-005 | C12: {=IFERROR(A12 - LOOKUP(2,1/($B$2:$B$100=B12)/($A$2:$A$100<A12),$A$2:$A$100),0)} -> 7 | G12: 45320 | H12: MCH-005 | I12: =IFERROR(AVERAGEIFS(oee_daily!O:O,oee_daily!C:C,H12,oee_daily!B:B,"<"&G12),0) -> 0.75311548 | J12: =IF(_xlfn.MINIFS($G$3:$G$1000, $H$3:$H$1000, H12, $G$3:$G$1000, ">"&G12)=0, 0, IFERROR(AVERAGEIFS(oee_daily!O:O, oee_daily!C:C, H12, oee_daily!B:B, ">"&G12, oee_daily!B:B, "<="&_xlfn.MINIFS($G$3:$G$1000, $H$3:$H$1000, H12, $G$3:$G$1000, ">"&G12)), 0)) -> 0.75304762 | K12: 1843.84 | L12: =IF(OR(I12=0, J12=0), 0, J12-I12) -> -6.7857143e-05 | M12: TECH-03 | N12: =IFERROR(L12/K12,0) -> -3.6802078e-08 | O12: TECH-02 | P12: 0.0057986017 | W12: Planned | X12: 2012
A13: 45320 | B13: MCH-003 | C13: {=IFERROR(A13 - LOOKUP(2,1/($B$2:$B$100=B13)/($A$2:$A$100<A13),$A$2:$A$100),0)} -> 21 | G13: 45320 | H13: MCH-003 | I13: =IFERROR(AVERAGEIFS(oee_daily!O:O,oee_daily!C:C,H13,oee_daily!B:B,"<"&G13),0) -> 0.73860476 | J13: =IF(_xlfn.MINIFS($G$3:$G$1000, $H$3:$H$1000, H13, $G$3:$G$1000, ">"&G13)=0, 0, IFERROR(AVERAGEIFS(oee_daily!O:O, oee_daily!C:C, H13, oee_daily!B:B, ">"&G13, oee_daily!B:B, "<="&_xlfn.MINIFS($G$3:$G$1000, $H$3:$H$1000, H13, $G$3:$G$1000, ">"&G13)), 0)) -> 0.74751905 | K13: 1791.29 | L13: =IF(OR(I13=0, J13=0), 0, J13-I13) -> 0.0089142857 | M13: TECH-02 | N13: =IFERROR(L13/K13,0) -> 4.9764615e-06 | O13: TECH-01 | P13: -0.0016818115 | W13: Unplanned | X13: 1861
A14: 45327 | B14: MCH-005 | C14: {=IFERROR(A14 - LOOKUP(2,1/($B$2:$B$100=B14)/($A$2:$A$100<A14),$A$2:$A$100),0)} -> 7 | G14: 45327 | H14: MCH-005 | I14: =IFERROR(AVERAGEIFS(oee_daily!O:O,oee_daily!C:C,H14,oee_daily!B:B,"<"&G14),0) -> 0.75254 | J14: =IF(_xlfn.MINIFS($G$3:$G$1000, $H$3:$H$1000, H14, $G$3:$G$1000, ">"&G14)=0, 0, IFERROR(AVERAGEIFS(oee_daily!O:O, oee_daily!C:C, H14, oee_daily!B:B, ">"&G14, oee_daily!B:B, "<="&_xlfn.MINIFS($G$3:$G$1000, $H$3:$H$1000, H14, $G$3:$G$1000, ">"&G14)), 0)) -> 0.74974286 | K14: 1726.87 | L14: =IF(OR(I14=0, J14=0), 0, J14-I14) -> -0.0027971429 | M14: TECH-01 | N14: =IFERROR(L14/K14,0) -> -1.6197762e-06 | O14: TECH-05 | P14: -0.019056984 | W14: MCH-005
A15: 45327 | B15: MCH-003 | C15: {=IFERROR(A15 - LOOKUP(2,1/($B$2:$B$100=B15)/($A$2:$A$100<A15),$A$2:$A$100),0)} -> 7 | G15: 45327 | H15: MCH-003 | I15: =IFERROR(AVERAGEIFS(oee_daily!O:O,oee_daily!C:C,H15,oee_daily!B:B,"<"&G15),0) -> 0.73880952 | J15: =IF(_xlfn.MINIFS($G$3:$G$1000, $H$3:$H$1000, H15, $G$3:$G$1000, ">"&G15)=0, 0, IFERROR(AVERAGEIFS(oee_daily!O:O, oee_daily!C:C, H15, oee_daily!B:B, ">"&G15, oee_daily!B:B, "<="&_xlfn.MINIFS($G$3:$G$1000, $H$3:$H$1000, H15, $G$3:$G$1000, ">"&G15)), 0)) -> 0.7292381 | K15: 1732.51 | L15: =IF(OR(I15=0, J15=0), 0, J15-I15) -> -0.0095714286 | M15: TECH-02 | N15: =IFERROR(L15/K15,0) -> -5.5246022e-06 | O15: Grand Total | P15: 0.0036887985 | W15: Planned | X15: 1749
A16: 45334 | B16: MCH-004 | C16: {=IFERROR(A16 - LOOKUP(2,1/($B$2:$B$100=B16)/($A$2:$A$100<A16),$A$2:$A$100),0)} -> 21 | G16: 45334 | H16: MCH-004 | I16: =IFERROR(AVERAGEIFS(oee_daily!O:O,oee_daily!C:C,H16,oee_daily!B:B,"<"&G16),0) -> 0.7281373 | J16: =IF(_xlfn.MINIFS($G$3:$G$1000, $H$3:$H$1000, H16, $G$3:$G$1000, ">"&G16)=0, 0, IFERROR(AVERAGEIFS(oee_daily!O:O, oee_daily!C:C, H16, oee_daily!B:B, ">"&G16, oee_daily!B:B, "<="&_xlfn.MINIFS($G$3:$G$1000, $H$3:$H$1000, H16, $G$3:$G$1000, ">"&G16)), 0)) -> 0.75632857 | K16: 135.46 | L16: =IF(OR(I16=0, J16=0), 0, J16-I16) -> 0.02819127 | M16: TECH-04 | N16: =IFERROR(L16/K16,0) -> 0.00020811509 | W16: Unplanned | X16: 1958
A17: 45334 | B17: MCH-003 | C17: {=IFERROR(A17 - LOOKUP(2,1/($B$2:$B$100=B17)/($A$2:$A$100<A17),$A$2:$A$100),0)} -> 7 | G17: 45334 | H17: MCH-003 | I17: =IFERROR(AVERAGEIFS(oee_daily!O:O,oee_daily!C:C,H17,oee_daily!B:B,"<"&G17),0) -> 0.73882063 | J17: =IF(_xlfn.MINIFS($G$3:$G$1000, $H$3:$H$1000, H17, $G$3:$G$1000, ">"&G17)=0, 0, IFERROR(AVERAGEIFS(oee_daily!O:O, oee_daily!C:C, H17, oee_daily!B:B, ">"&G17, oee_daily!B:B, "<="&_xlfn.MINIFS($G$3:$G$1000, $H$3:$H$1000, H17, $G$3:$G$1000, ">"&G17)), 0)) -> 0.71552381 | K17: 954.21 | L17: =IF(OR(I17=0, J17=0), 0, J17-I17) -> -0.023296825 | M17: TECH-05 | N17: =IFERROR(L17/K17,0) -> -2.4414778e-05 | O17: Row Labels | P17: Average of OEE Before | Q17: Average of OEE After: | W17: Grand Total | X17: 19341
A18: 45341 | B18: MCH-005 | C18: {=IFERROR(A18 - LOOKUP(2,1/($B$2:$B$100=B18)/($A$2:$A$100<A18),$A$2:$A$100),0)} -> 14 | G18: 45341 | H18: MCH-005 | I18: =IFERROR(AVERAGEIFS(oee_daily!O:O,oee_daily!C:C,H18,oee_daily!B:B,"<"&G18),0) -> 0.75347483 | J18: =IF(_xlfn.MINIFS($G$3:$G$1000, $H$3:$H$1000, H18, $G$3:$G$1000, ">"&G18)=0, 0, IFERROR(AVERAGEIFS(oee_daily!O:O, oee_daily!C:C, H18, oee_daily!B:B, ">"&G18, oee_daily!B:B, "<="&_xlfn.MINIFS($G$3:$G$1000, $H$3:$H$1000, H18, $G$3:$G$1000, ">"&G18)), 0)) -> 0.72622857 | K18: 1349.53 | L18: =IF(OR(I18=0, J18=0), 0, J18-I18) -> -0.027246259 | M18: TECH-01 | N18: =IFERROR(L18/K18,0) -> -2.0189443e-05 | O18: MCH-002 | P18: 0.73869405 | Q18: 0.36799286
A19: 45341 | B19: MCH-003 | C19: {=IFERROR(A19 - LOOKUP(2,1/($B$2:$B$100=B19)/($A$2:$A$100<A19),$A$2:$A$100),0)} -> 7 | G19: 45341 | H19: MCH-003 | I19: =IFERROR(AVERAGEIFS(oee_daily!O:O,oee_daily!C:C,H19,oee_daily!B:B,"<"&G19),0) -> 0.73539796 | J19: =IF(_xlfn.MINIFS($G$3:$G$1000, $H$3:$H$1000, H19, $G$3:$G$1000, ">"&G19)=0, 0, IFERROR(AVERAGEIFS(oee_daily!O:O, oee_daily!C:C, H19, oee_daily!B:B, ">"&G19, oee_daily!B:B, "<="&_xlfn.MINIFS($G$3:$G$1000, $H$3:$H$1000, H19, $G$3:$G$1000, ">"&G19)), 0)) -> 0.72907619 | K19: 1371.2 | L19: =IF(OR(I19=0, J19=0), 0, J19-I19) -> -0.0063217687 | M19: TECH-02 | N19: =IFERROR(L19/K19,0) -> -4.6103914e-06 | O19: MCH-003 | P19: 0.73866369 | Q19: 0.63373016
A20: 45341 | B20: MCH-004 | C20: {=IFERROR(A20 - LOOKUP(2,1/($B$2:$B$100=B20)/($A$2:$A$100<A20),$A$2:$A$100),0)} -> 7 | G20: 45341 | H20: MCH-004 | I20: =IFERROR(AVERAGEIFS(oee_daily!O:O,oee_daily!C:C,H20,oee_daily!B:B,"<"&G20),0) -> 0.73304694 | J20: =IF(_xlfn.MINIFS($G$3:$G$1000, $H$3:$H$1000, H20, $G$3:$G$1000, ">"&G20)=0, 0, IFERROR(AVERAGEIFS(oee_daily!O:O, oee_daily!C:C, H20, oee_daily!B:B, ">"&G20, oee_daily!B:B, "<="&_xlfn.MINIFS($G$3:$G$1000, $H$3:$H$1000, H20, $G$3:$G$1000, ">"&G20)), 0)) -> 0.74506667 | K20: 1179.01 | L20: =IF(OR(I20=0, J20=0), 0, J20-I20) -> 0.012019728 | M20: TECH-01 | N20: =IFERROR(L20/K20,0) -> 1.0194763e-05 | O20: MCH-004 | P20: 0.73275607 | Q20: 0.61542196
A21: 45348 | B21: MCH-001 | C21: {=IFERROR(A21 - LOOKUP(2,1/($B$2:$B$100=B21)/($A$2:$A$100<A21),$A$2:$A$100),0)} -> 35 | G21: 45348 | H21: MCH-001 | I21: =IFERROR(AVERAGEIFS(oee_daily!O:O,oee_daily!C:C,H21,oee_daily!B:B,"<"&G21),0) -> 0.7311631 | J21: =IF(_xlfn.MINIFS($G$3:$G$1000, $H$3:$H$1000, H21, $G$3:$G$1000, ">"&G21)=0, 0, IFERROR(AVERAGEIFS(oee_daily!O:O, oee_daily!C:C, H21, oee_daily!B:B, ">"&G21, oee_daily!B:B, "<="&_xlfn.MINIFS($G$3:$G$1000, $H$3:$H$1000, H21, $G$3:$G$1000, ">"&G21)), 0)) -> 0.76228095 | K21: 1037.64 | L21: =IF(OR(I21=0, J21=0), 0, J21-I21) -> 0.031117857 | M21: TECH-03 | N21: =IFERROR(L21/K21,0) -> 2.9989069e-05 | O21: MCH-005 | P21: 0.64249933 | Q21: 0.64215748
A22: 45355 | B22: MCH-003 | C22: {=IFERROR(A22 - LOOKUP(2,1/($B$2:$B$100=B22)/($A$2:$A$100<A22),$A$2:$A$100),0)} -> 14 | G22: 45355 | H22: MCH-003 | I22: =IFERROR(AVERAGEIFS(oee_daily!O:O,oee_daily!C:C,H22,oee_daily!B:B,"<"&G22),0) -> 0.73340688 | J22: =IF(_xlfn.MINIFS($G$3:$G$1000, $H$3:$H$1000, H22, $G$3:$G$1000, ">"&G22)=0, 0, IFERROR(AVERAGEIFS(oee_daily!O:O, oee_daily!C:C, H22, oee_daily!B:B, ">"&G22, oee_daily!B:B, "<="&_xlfn.MINIFS($G$3:$G$1000, $H$3:$H$1000, H22, $G$3:$G$1000, ">"&G22)), 0)) -> 0.77375238 | K22: 1252.37 | L22: =IF(OR(I22=0, J22=0), 0, J22-I22) -> 0.040345503 | M22: TECH-02 | N22: =IFERROR(L22/K22,0) -> 3.2215322e-05 | O22: MCH-001 | P22: 0.60492425 | Q22: 0.61399048 | W22: Row Labels | X22: Average of cost_usd | Z22: Count of result | AA22: Column Labels
A23: 45355 | B23: MCH-001 | C23: {=IFERROR(A23 - LOOKUP(2,1/($B$2:$B$100=B23)/($A$2:$A$100<A23),$A$2:$A$100),0)} -> 7 | G23: 45355 | H23: MCH-001 | I23: =IFERROR(AVERAGEIFS(oee_daily!O:O,oee_daily!C:C,H23,oee_daily!B:B,"<"&G23),0) -> 0.73242222 | J23: =IF(_xlfn.MINIFS($G$3:$G$1000, $H$3:$H$1000, H23, $G$3:$G$1000, ">"&G23)=0, 0, IFERROR(AVERAGEIFS(oee_daily!O:O, oee_daily!C:C, H23, oee_daily!B:B, ">"&G23, oee_daily!B:B, "<="&_xlfn.MINIFS($G$3:$G$1000, $H$3:$H$1000, H23, $G$3:$G$1000, ">"&G23)), 0)) -> 0.75086667 | K23: 525.08 | L23: =IF(OR(I23=0, J23=0), 0, J23-I23) -> 0.018444444 | M23: TECH-03 | N23: =IFERROR(L23/K23,0) -> 3.5126922e-05 | O23: Grand Total | P23: 0.6847004 | Q23: 0.60870264 | W23: Predictive | X23: 1044.7483 | Z23: Row Labels | AA23: MCH-001 | AB23: MCH-002 | AC23: MCH-003 | AD23: MCH-004 | AE23: MCH-005 | AF23: Grand Total
A24: 45355 | B24: MCH-004 | C24: {=IFERROR(A24 - LOOKUP(2,1/($B$2:$B$100=B24)/($A$2:$A$100<A24),$A$2:$A$100),0)} -> 14 | G24: 45355 | H24: MCH-004 | I24: =IFERROR(AVERAGEIFS(oee_daily!O:O,oee_daily!C:C,H24,oee_daily!B:B,"<"&G24),0) -> 0.73487672 | J24: =IF(_xlfn.MINIFS($G$3:$G$1000, $H$3:$H$1000, H24, $G$3:$G$1000, ">"&G24)=0, 0, IFERROR(AVERAGEIFS(oee_daily!O:O, oee_daily!C:C, H24, oee_daily!B:B, ">"&G24, oee_daily!B:B, "<="&_xlfn.MINIFS($G$3:$G$1000, $H$3:$H$1000, H24, $G$3:$G$1000, ">"&G24)), 0)) -> 0.74280952 | K24: 754.62 | L24: =IF(OR(I24=0, J24=0), 0, J24-I24) -> 0.0079328042 | M24: TECH-01 | N24: =IFERROR(L24/K24,0) -> 1.0512316e-05 | W24: Preventive | X24: 1170.765 | Z24: Escalated | AA24: 2 | AC24: 1 | AF24: 3
A25: 45362 | B25: MCH-004 | C25: {=IFERROR(A25 - LOOKUP(2,1/($B$2:$B$100=B25)/($A$2:$A$100<A25),$A$2:$A$100),0)} -> 7 | G25: 45362 | H25: MCH-004 | I25: =IFERROR(AVERAGEIFS(oee_daily!O:O,oee_daily!C:C,H25,oee_daily!B:B,"<"&G25),0) -> 0.73657905 | J25: =IF(_xlfn.MINIFS($G$3:$G$1000, $H$3:$H$1000, H25, $G$3:$G$1000, ">"&G25)=0, 0, IFERROR(AVERAGEIFS(oee_daily!O:O, oee_daily!C:C, H25, oee_daily!B:B, ">"&G25, oee_daily!B:B, "<="&_xlfn.MINIFS($G$3:$G$1000, $H$3:$H$1000, H25, $G$3:$G$1000, ">"&G25)), 0)) -> 0.7217619 | K25: 885.52 | L25: =IF(OR(I25=0, J25=0), 0, J25-I25) -> -0.014817143 | M25: TECH-05 | N25: =IFERROR(L25/K25,0) -> -1.6732703e-05 | W25: Inspection | X25: 1196.22 | Z25: Partially Resolved | AC25: 1 | AD25: 1 | AE25: 2 | AF25: 4
A26: 45362 | B26: MCH-001 | C26: {=IFERROR(A26 - LOOKUP(2,1/($B$2:$B$100=B26)/($A$2:$A$100<A26),$A$2:$A$100),0)} -> 7 | G26: 45362 | H26: MCH-001 | I26: =IFERROR(AVERAGEIFS(oee_daily!O:O,oee_daily!C:C,H26,oee_daily!B:B,"<"&G26),0) -> 0.7354681 | J26: =IF(_xlfn.MINIFS($G$3:$G$1000, $H$3:$H$1000, H26, $G$3:$G$1000, ">"&G26)=0, 0, IFERROR(AVERAGEIFS(oee_daily!O:O, oee_daily!C:C, H26, oee_daily!B:B, ">"&G26, oee_daily!B:B, "<="&_xlfn.MINIFS($G$3:$G$1000, $H$3:$H$1000, H26, $G$3:$G$1000, ">"&G26)), 0)) -> 0 | K26: 981.13 | L26: =IF(OR(I26=0, J26=0), 0, J26-I26) -> 0 | M26: TECH-01 | N26: =IFERROR(L26/K26,0) -> 0 | W26: Corrective | X26: 1255.7114 | Z26: Resolved | AA26: 4 | AB26: 2 | AC26: 5 | AD26: 5 | AE26: 5 | AF26: 21
A27: 45369 | B27: MCH-005 | C27: {=IFERROR(A27 - LOOKUP(2,1/($B$2:$B$100=B27)/($A$2:$A$100<A27),$A$2:$A$100),0)} -> 28 | G27: 45369 | H27: MCH-005 | I27: =IFERROR(AVERAGEIFS(oee_daily!O:O,oee_daily!C:C,H27,oee_daily!B:B,"<"&G27),0) -> 0.7431039 | J27: =IF(_xlfn.MINIFS($G$3:$G$1000, $H$3:$H$1000, H27, $G$3:$G$1000, ">"&G27)=0, 0, IFERROR(AVERAGEIFS(oee_daily!O:O, oee_daily!C:C, H27, oee_daily!B:B, ">"&G27, oee_daily!B:B, "<="&_xlfn.MINIFS($G$3:$G$1000, $H$3:$H$1000, H27, $G$3:$G$1000, ">"&G27)), 0)) -> 0 | K27: 1915.01 | L27: =IF(OR(I27=0, J27=0), 0, J27-I27) -> 0 | M27: TECH-02 | N27: =IFERROR(L27/K27,0) -> 0 | W27: Grand Total | X27: 1171.3618 | Z27: Grand Total | AA27: 6 | AB27: 2 | AC27: 7 | AD27: 6 | AE27: 7 | AF27: 28
A28: 45369 | B28: MCH-003 | C28: {=IFERROR(A28 - LOOKUP(2,1/($B$2:$B$100=B28)/($A$2:$A$100<A28),$A$2:$A$100),0)} -> 14 | G28: 45369 | H28: MCH-003 | I28: =IFERROR(AVERAGEIFS(oee_daily!O:O,oee_daily!C:C,H28,oee_daily!B:B,"<"&G28),0) -> 0.74127749 | J28: =IF(_xlfn.MINIFS($G$3:$G$1000, $H$3:$H$1000, H28, $G$3:$G$1000, ">"&G28)=0, 0, IFERROR(AVERAGEIFS(oee_daily!O:O, oee_daily!C:C, H28, oee_daily!B:B, ">"&G28, oee_daily!B:B, "<="&_xlfn.MINIFS($G$3:$G$1000, $H$3:$H$1000, H28, $G$3:$G$1000, ">"&G28)), 0)) -> 0 | K28: 1928.2 | L28: =IF(OR(I28=0, J28=0), 0, J28-I28) -> 0 | M28: TECH-03 | N28: =IFERROR(L28/K28,0) -> 0
A29: 45376 | B29: MCH-004 | C29: {=IFERROR(A29 - LOOKUP(2,1/($B$2:$B$100=B29)/($A$2:$A$100<A29),$A$2:$A$100),0)} -> 14 | G29: 45376 | H29: MCH-004 | I29: =IFERROR(AVERAGEIFS(oee_daily!O:O,oee_daily!C:C,H29,oee_daily!B:B,"<"&G29),0) -> 0.73433135 | J29: =IF(_xlfn.MINIFS($G$3:$G$1000, $H$3:$H$1000, H29, $G$3:$G$1000, ">"&G29)=0, 0, IFERROR(AVERAGEIFS(oee_daily!O:O, oee_daily!C:C, H29, oee_daily!B:B, ">"&G29, oee_daily!B:B, "<="&_xlfn.MINIFS($G$3:$G$1000, $H$3:$H$1000, H29, $G$3:$G$1000, ">"&G29)), 0)) -> 0 | K29: 1529.59 | L29: =IF(OR(I29=0, J29=0), 0, J29-I29) -> 0 | M29: TECH-02 | N29: =IFERROR(L29/K29,0) -> 0 | W29: Row Labels | X29: Count of reported_by
W30: OP-008 | X30: 168
W31: OP-012 | X31: 166
W32: OP-003 | X32: 162
W33: OP-007 | X33: 160 | Z33: Row Labels | AA33: Sum of units_produced
W34: OP-002 | X34: 158 | Z34: PROD-A01 | AA34: 111508
W35: OP-010 | X35: 157 | Z35: PROD-A02 | AA35: 122108
W36: OP-005 | X36: 157 | Z36: PROD-B01 | AA36: 108656
W37: OP-006 | X37: 143 | Z37: PROD-B02 | AA37: 105151
W38: OP-004 | X38: 142 | Z38: PROD-C01 | AA38: 101218
W39: OP-001 | X39: 142 | Z39: Grand Total | AA39: 548641
W40: OP-011 | X40: 141
...

Sheet Production&Quality
AB14: #1E3A5F | AC14: Navy Blue
AB15: #6B7280 | AC15: Steel Gray
AB16: #2B2D42 | AC16: Charcoal
AB17: #D1D5DB | AC17: Silver
AB18: #F3F4F6 | AC18: White Smoke

Sheet Maintenance
